<?xml version="1.0" ?>
<sdf version="1.5">

<model name="simplified_biped">
    <link name="hanging_thing">
        <self_collide> 1 </self_collide>

        <pose> 0 0 1.7 0 0 0 </pose>

        <inertial>
            <mass>100</mass>

            <inertia>
                <ixx>0.3</ixx>
                <iyy>166</iyy>
                <izz>175</izz>
                <ixy>0</ixy>
                <ixz>0</ixz>
                <iyz>0</iyz>
            </inertia>
        </inertial>

        <collision name="torso_connection_collision">
            <geometry>
                <box>
                    <size> 0.80 0.3 0.1 </size>
                </box>
            </geometry>
        </collision>

        <visual name="torso_connection_visual">
            <geometry>
                <box>
                    <size> 0.80 0.3 0.1 </size>
                </box>
            </geometry>
        </visual>
    </link>

    <link name="rod_1">
        <self_collide> 1 </self_collide>

        <pose> 1 0 0.5 1.57 0 0 </pose>

        <inertial>
            <mass>100</mass>

            <inertia>
                <ixx>0.3</ixx>
                <iyy>166</iyy>
                <izz>175</izz>
                <ixy>0</ixy>
                <ixz>0</ixz>
                <iyz>0</iyz>
            </inertia>
        </inertial>

        <collision name="rod_1_collision">
            <geometry>
                <box>
                    <size> 0.15 1 0.15 </size>
                </box>
            </geometry>
        </collision>

        <visual name="rod_1_visual">
            <geometry>
                <box>
                    <size> 0.15 1 0.15 </size>
                </box>
            </geometry>
        </visual>
    </link>

    <link name="rod_2">
        <self_collide> 1 </self_collide>

        <pose> -1 0 0.5 1.57 0 0 </pose>

        <inertial>
            <mass>100</mass>

            <inertia>
                <ixx>0.3</ixx>
                <iyy>166</iyy>
                <izz>175</izz>
                <ixy>0</ixy>
                <ixz>0</ixz>
                <iyz>0</iyz>
            </inertia>
        </inertial>

        <collision name="rod_2_collision">
            <geometry>
                <box>
                    <size> 0.15 1 0.15 </size>
                </box>
            </geometry>
        </collision>

        <visual name="rod_2_visual">
            <geometry>
                <box>
                    <size> 0.15 1 0.15 </size>
                </box>
            </geometry>
        </visual>
    </link>

    <link name="rod_3">
        <self_collide> 1 </self_collide>

        <pose> 0 1 0.5 1.57 0 0 </pose>

        <inertial>
            <mass>100</mass>

            <inertia>
                <ixx>0.3</ixx>
                <iyy>166</iyy>
                <izz>175</izz>
                <ixy>0</ixy>
                <ixz>0</ixz>
                <iyz>0</iyz>
            </inertia>
        </inertial>

        <collision name="rod_3_collision">
            <geometry>
                <box>
                    <size> 0.15 1 0.15 </size>
                </box>
            </geometry>
        </collision>

        <visual name="rod_3_visual">
            <geometry>
                <box>
                    <size> 0.15 1 0.15 </size>
                </box>
            </geometry>
        </visual>
    </link>

    <link name="rod_4">
        <self_collide> 1 </self_collide>

        <pose> 0 -1 0.5 1.57 0 0 </pose>

        <inertial>
            <mass>100</mass>

            <inertia>
                <ixx>0.3</ixx>
                <iyy>166</iyy>
                <izz>175</izz>
                <ixy>0</ixy>
                <ixz>0</ixz>
                <iyz>0</iyz>
            </inertia>
        </inertial>

        <collision name="rod_4_collision">
            <geometry>
                <box>
                    <size> 0.15 1 0.15 </size>
                </box>
            </geometry>
        </collision>

        <visual name="rod_4_visual">
            <geometry>
                <box>
                    <size> 0.15 1 0.15 </size>
                </box>
            </geometry>
        </visual>
    </link>

    <joint name="temp_joint_1" type="fixed">
        <parent>hanging_thing</parent>
        <child>torso_connection</child>
    </joint>

    <joint name="temp_joint_2" type="fixed">
        <parent>rod_1</parent>
        <child>hanging_thing</child>
    </joint>

    <joint name="temp_joint_3" type="fixed">
        <parent>rod_2</parent>
        <child>hanging_thing</child>
    </joint>

    <joint name="temp_joint_4" type="fixed">
        <parent>rod_3</parent>
        <child>hanging_thing</child>
    </joint>

    <joint name="temp_joint_5" type="fixed">
        <parent>rod_4</parent>
        <child>hanging_thing</child>
    </joint>
    
    <link name="torso_connection">
        <self_collide> 1 </self_collide>

        <pose> 0 0 1.48 0 0 0 </pose>

        <inertial>
            <mass>10</mass>

            <inertia>
                <ixx>0.05121</ixx>
                <iyy>0.2096</iyy>
                <izz>0.2281</izz>
            </inertia>
        </inertial>

        <collision name="torso_connection_collision">
            <geometry>
                <mesh>
	   		 		<uri>model://simplified_biped/meshes/torso_connection.stl</uri>
				</mesh>
            </geometry>
        </collision>

        <visual name="torso_connection_visual">
            <geometry>
                <mesh>
					<uri>model://simplified_biped/meshes/torso_connection.stl</uri>
				</mesh>
            </geometry>
        </visual>
    </link>

    <!--Left leg-->
    <link name="left_lower_leg">

        <self_collide>1</self_collide>

        <pose> -0.15 0 0.64 0 0 0 </pose>

            <inertial>
                <mass>0.83</mass>
            <inertia>
                <ixx>0.015</ixx>
                <iyy>0.014</iyy>
                <izz>0.001</izz>
                <ixy>0</ixy>
                <ixz>0</ixz>
                <iyz>0</iyz>
                </inertia>
            </inertial>
            
            <collision name="left_lower_leg_collision">
                <geometry>
                    <box>
                        <size>0.06 0.06 0.35</size>
                    </box>
                </geometry>
            </collision>

            <visual name="left_lower_leg_visual">
                <geometry>
                    <box>
                        <size>0.06 0.06 0.4</size>
                    </box>
                </geometry>
            </visual>
    </link>

    <link name="left_knee">

        <self_collide>1</self_collide>
        <pose> -0.15 0 0.84 0 1.570796 0</pose>

        <inertial>
            <mass>0.1</mass>
            <inertia>
                <ixx>3.794e-05</ixx>
                <iyy>3.252e-05</iyy>
                <izz>3.794e-05</izz>
                <ixy>0</ixy>
                <ixz>0</ixz>
                <iyz>0</iyz>
            </inertia>
        </inertial>

        <collision name="left_knee_collision">
            <geometry>
                <cylinder>
                    <radius>0.02</radius>
                    <length>0.05</length>
                </cylinder>
            </geometry>
        </collision>

        <visual name="left_knee_visual">
            <pose> 0 0 0 0 0 0</pose>
            <geometry>
                <cylinder>
                    <radius>0.02</radius>
                    <length>0.05</length>
                </cylinder>
            </geometry>
        </visual>
    </link>

    <link name="left_upper_leg">

        <self_collide>1</self_collide>

        <pose> -0.15 0 1.05 0 0 0 </pose> 

        <inertial>
            <mass>2.1</mass>
            <inertia>
                <ixx>0.052</ixx>
                <iyy>0.05</iyy>
                <izz>0.007</izz>
                <ixy>0</ixy>
                <ixz>0</ixz>
                <iyz>0</iyz>
            </inertia>
        </inertial>
        
        <collision name="left_upper_leg_collision">
            <geometry>
                <mesh>
					<uri>model://simplified_biped/meshes/upper_leg_350mm.stl</uri>
				</mesh>
            </geometry>
        </collision>

        <visual name="left_upper_leg_visual">
            <geometry>
                <mesh>
					<uri>model://simplified_biped/meshes/upper_leg_350mm.stl</uri>
				</mesh>
            </geometry>
        </visual>
    </link>

    <link name="left_foot_base">

        <self_collide>1</self_collide>
        <pose> -0.15 0 0.41 0 0 0</pose>

        <inertial>
            <mass>0.1</mass>
            <inertia>
                <ixx>2.733e-04</ixx>
                <iyy>5.666e-05</iyy>
                <izz>3.233e-04</izz>
                <ixy>0</ixy>
                <ixz>0</ixz>
                <iyz>0</iyz>
            </inertia>
        </inertial>

        <collision name="left_foot_base_collision">
            <geometry>
                <box>
                    <size> 0.08 0.18 0.02</size>
                </box>
            </geometry>
        </collision>

        <visual name="left_foot_base_visual">
            <geometry>
                <box>
                    <size> 0.08 0.18 0.02</size>
                </box>
            </geometry>
        </visual>
    </link>

    <link name="left_ankle">

        <self_collide>1</self_collide>
        <pose> -0.15 0 0.44 0 1.570796 0 </pose>

        <inertial>
            <mass>0.01</mass>
            <inertia>
                <ixx>3.05e-05</ixx>
                <iyy>3.05e-05</iyy>
                <izz>3.088e-06</izz>
                <ixy>0</ixy>
                <ixz>0</ixz>
                <iyz>0</iyz>
            </inertia>
        </inertial>

        <collision name="left_ankle_collision">
            <geometry>
                <cylinder>
                    <radius>0.005</radius>
                    <length>0.06</length>
                </cylinder>
            </geometry>
        </collision>

        <visual name="left_ankle_visual">
            <geometry>
                <cylinder>
                    <radius>0.005</radius>
                    <length>0.06</length>
                </cylinder>
            </geometry>
        </visual>
    </link>

    <link name="left_hip_axis_1">

        <self_collide>1</self_collide>
        <pose> -0.0765 0 1.26 0 1.570796 0 </pose>

        <inertial>
            <mass>4</mass>
            <inertia>
                <ixx>0.007</ixx>
                <iyy>0.007</iyy>
                <izz>0.012</izz>
            </inertia>
        </inertial>

        <collision name="left_hip_axis_1_collision">
            <geometry>
                <cylinder>
                    <radius>0.04</radius>
                    <length>0.04</length>
                </cylinder>
            </geometry>
        </collision>

        <visual name="left_hip_axis_1_visual">
            <pose> 0 0 0 0 0 0</pose>
            <geometry>
                <mesh>
					<uri>model://simplified_biped/meshes/actuator_scaled.stl</uri>
				</mesh>
            </geometry>
        </visual>
    </link>

	<link name="left_knee_actuator">

        <self_collide>1</self_collide>
        <pose> -0.1625 0 1.26 0 -1.570796 0 </pose>

        <inertial>
            <mass>4</mass>
            <inertia>
                <ixx>0.007</ixx>
                <iyy>0.007</iyy>
                <izz>0.012</izz>
            </inertia>
        </inertial>

        <collision name="left_knee_actuator_collision">
            <geometry>
                <cylinder>
                    <radius>0.04</radius>
                    <length>0.04</length>
                </cylinder>
            </geometry>
        </collision>

        <visual name="left_knee_actuator_visual">
            <pose> 0 0 0 0 0 0</pose>
            <geometry>
                <mesh>
					<uri>model://simplified_biped/meshes/actuator_scaled.stl</uri>
				</mesh>
            </geometry>
        </visual>
    </link>

    <link name="left_hip_axis_2">

        <self_collide>1</self_collide>
        <pose> -0.15 -0.12 1.26 1.570796327 0 0 </pose>
        
        <inertial>
            <mass>4</mass>
            <inertia>
                <ixx>0.007</ixx>
                <iyy>0.007</iyy>
                <izz>0.012</izz>
            </inertia>
        </inertial>

        <collision name="left_hip_axis_2_collision">
            <geometry>
                <mesh>
					<uri>model://simplified_biped/meshes/actuator_scaled.stl</uri>
				</mesh>
            </geometry>
        </collision>

        <visual name="left_hip_axis_2_visual">
            <pose> 0 0 0 0 0 0</pose>
            <geometry>
                <mesh>
					<uri>model://simplified_biped/meshes/actuator_scaled.stl</uri>
				</mesh>
            </geometry>
        </visual>
    </link>

    <link name="left_hip_axis_3">

        <self_collide>1</self_collide>
        <pose> -0.15 0 1.377 0 0 0 </pose> <!--145mm from center of hip axis 2-->

        <inertial>
            <mass>4</mass>
            <inertia>
                <ixx>0.007</ixx>
                <iyy>0.007</iyy>
                <izz>0.012</izz>
            </inertia>
        </inertial>

        <collision name="left_hip_axis_3_collision">
            <geometry>
                <mesh>
					<uri>model://simplified_biped/meshes/actuator_scaled.stl</uri>
				</mesh>
            </geometry>
        </collision>

        <visual name="left_hip_axis_3_visual">
            <geometry>
                <mesh>
					<uri>model://simplified_biped/meshes/actuator_scaled.stl</uri>
				</mesh>
            </geometry>
        </visual>
    </link>

    <joint type="revolute" name="left_knee_lower_leg_joint">

        <pose> 0 0 0.205 0 0 0 </pose>

        <parent>left_knee</parent>

        <child>left_lower_leg</child>
        
        <axis>
            <xyz>1 0 0 </xyz>
            <limit>
                <lower>-2.5</lower>
                <upper>2.5</upper>
            </limit>
        </axis>
    </joint>

    <joint type="revolute" name="left_hip_axis_1_upper_leg_joint">

        <pose> 0 0 0.205 0 0 0 </pose>

        <parent>left_hip_axis_1</parent>

        <child>left_upper_leg</child>

        <axis>
            <xyz>1 0 0 </xyz>
            <limit>
                <lower>-0.7</lower>
                <upper>2.5</upper>
            </limit>
        </axis>
    </joint>

	<joint type="fixed" name="left_hip_axis_1_knee_actuator_joint">
        <pose> -0.145 0 0 0 -1.570796 0 </pose>

        <parent>left_hip_axis_1</parent>
        <child>left_knee_actuator</child>
    </joint>

	<joint type="revolute" name="left_hip_axis_2_hip_axis_1_joint">
        <pose> 0 -0.12 -0.0735 0 0 0 </pose>

        <parent>left_hip_axis_2</parent>
        <child>left_hip_axis_1</child>

        <axis>
            <xyz> 0 1 0 </xyz>
            <limit>
                <lower>-2.5</lower>
                <upper>2.5</upper>
            </limit>
        </axis>
    </joint>

    <joint type="revolute" name="left_hip_axis_3_hip_axis_2_joint">
        <pose> 0 0.12 -0.117 0 0 0 </pose>

        <parent>left_hip_axis_3</parent>
        <child>left_hip_axis_2</child>

        <axis>
            <xyz> 0 1 0 </xyz>
            <limit>
                <lower>-1</lower>
                <upper>1</upper>
            </limit>
        </axis>
    </joint>

    <joint type="fixed" name="left_ankle_foot_base_joint">
        <pose> 0 0 0.03 0 0 0 </pose>

        <parent>left_ankle</parent>
        <child>left_foot_base</child>

        <!-- <axis>
            <xyz>1 0 0 </xyz>
            <limit>
                <lower>-1.57</lower>
                <upper>1.57</upper>
            </limit>
        </axis> -->
    </joint>

    <joint type="fixed" name="left_knee_upper_leg_joint">
        <pose>0 0 0 0 0 0 </pose>
        <parent>left_upper_leg</parent>
        <child>left_knee</child>
    </joint>

    <joint type="fixed" name="left_ankle_lower_leg_joint">
        <pose> 0 0 0 0 0 0 </pose>
        <parent>left_lower_leg</parent>
        <child>left_ankle</child>
    </joint>

	<joint type="fixed" name="left_torso_connection_joint">
        <pose> 0 0 0 0 0 0 </pose>
        <parent>torso_connection</parent>
        <child>left_hip_axis_3</child>
    </joint>


    <!-- Right leg -->
    <link name="right_lower_leg">

        <self_collide>1</self_collide>

        <pose> 0.15 0 0.635 0 0 0 </pose>

            <inertial>
                <mass>0.5</mass>
                <inertia>
                    <ixx>5.220e-03</ixx>
		            <iyy>5.220e-03</iyy>
		            <izz>2.078e-04</izz>
                    <ixy>0</ixy>
                    <ixz>0</ixz>
                    <iyz>0</iyz>
                </inertia>
            </inertial>
            
            <collision name="right_base_collision">
                <geometry>
                    <mesh>
						<uri>model://simplified_biped/meshes/lower_leg_350mm.stl</uri>
					</mesh>
                </geometry>
            </collision>

            <visual name="right_base_visual">
                <geometry>
                    <mesh>
		   		 		<uri>model://simplified_biped/meshes/lower_leg_350mm.stl</uri>
					</mesh>
                </geometry>
            </visual>
    </link>

    <link name="right_knee">

        <self_collide>1</self_collide>
        <pose> 0.15 0 0.84 0 1.570796 0</pose>

        <inertial>
            <mass>0.1</mass>
            <inertia>
                <ixx>3.794e-05</ixx>
                <iyy>3.252e-05</iyy>
                <izz>3.794e-05</izz>
                <ixy>0</ixy>
                <ixz>0</ixz>
                <iyz>0</iyz>
            </inertia>
        </inertial>

        <collision name="right_knee_collision">
            <geometry>
                <cylinder>
                    <radius>0.025</radius>
                    <length>0.05</length>
                </cylinder>
            </geometry>
        </collision>

        <visual name="right_knee_visual">
            <pose> 0 0 0 0 0 0</pose>
            <geometry>
                <cylinder>
                    <radius>0.025</radius>
                    <length>0.05</length>
                </cylinder>
            </geometry>
        </visual>
    </link>

    <link name="right_upper_leg">

        <self_collide>1</self_collide>

        <pose> 0.15 0 1.055 0 0 0 </pose> 

        <inertial>
            <mass>0.5</mass>
            <inertia>
                <ixx>5.220e-03</ixx>
                <iyy>5.220e-03</iyy>
                <izz>2.078e-04</izz>
                <ixy>0</ixy>
                <ixz>0</ixz>
                <iyz>0</iyz>
            </inertia>
        </inertial>

        <!-- To make them perfectly stacked: 0.65m height-->
        
        <collision name="right_upper_leg_collision">
            <geometry>
                <mesh>
					<uri>model://simplified_biped/meshes/upper_leg_350mm.stl</uri>
				</mesh>
            </geometry>
        </collision>

        <visual name="right_upper_leg_visual">
            <geometry>
                <mesh>
					<uri>model://simplified_biped/meshes/upper_leg_350mm.stl</uri>
				</mesh>
            </geometry>
        </visual>
    </link>

    <link name="right_foot_base">

        <self_collide>1</self_collide>
        <pose> 0.15 0 0.41 0 0 0</pose>

        <inertial>
            <mass>0.1</mass>
            <inertia>
                <ixx>2.733e-04</ixx>
                <iyy>5.666e-05</iyy>
                <izz>3.233e-04</izz>
                <ixy>0</ixy>
                <ixz>0</ixz>
                <iyz>0</iyz>
            </inertia>
        </inertial>

        <collision name="right_foot_base_collision">
            <geometry>
                <box>
                    <size> 0.08 0.18 0.02</size>
                </box>
            </geometry>
        </collision>

        <visual name="right_foot_base_visual">
            <geometry>
                <box>
                    <size> 0.08 0.18 0.02</size>
                </box>
            </geometry>
        </visual>
    </link>

    <link name="right_ankle">

        <self_collide>1</self_collide>
        <pose> 0.15 0 0.44 0 1.570796 0 </pose>

        <inertial>
            <mass>0.01</mass>
            <inertia>
                <ixx>3.05e-05</ixx>
                <iyy>3.05e-05</iyy>
                <izz>3.088e-06</izz>
                <ixy>0</ixy>
                <ixz>0</ixz>
                <iyz>0</iyz>
            </inertia>
        </inertial>

        <collision name="right_ankle_collision">
            <geometry>
                <cylinder>
                    <radius>0.005</radius>
                    <length>0.06</length>
                </cylinder>
            </geometry>
        </collision>

        <visual name="right_ankle_visual">
            <geometry>
                <cylinder>
                    <radius>0.005</radius>
                    <length>0.06</length>
                </cylinder>
            </geometry>
        </visual>
    </link>

    <link name="right_hip_axis_1">

        <self_collide>1</self_collide>
        <pose> 0.2 0 1.26 0 1.570796 0 </pose>

        <inertial>
            <mass>2.5</mass>
            <inertia>
                <ixx>0.004505</ixx>
                <iyy>0.004505</iyy>
                <izz>0.008515</izz>
            </inertia>
        </inertial>

        <collision name="right_hip_axis_1_collision">
            <geometry>
                <mesh>
					<uri>model://simplified_biped/meshes/actuator_scaled.stl</uri>
				</mesh>
            </geometry>
        </collision>

        <visual name="right_hip_axis_1_visual">
            <pose> 0 0 0 0 0 0</pose>
            <geometry>
                <mesh>
					<uri>model://simplified_biped/meshes/actuator_scaled.stl</uri>
				</mesh>
            </geometry>
        </visual>
    </link>

	<link name="right_knee_actuator">

        <self_collide>1</self_collide>
        <pose> 0.1 0 1.26 0 -1.570796 0 </pose>

        <inertial>
            <mass>2.5</mass>
            <inertia>
                <ixx>0.004505</ixx>
                <iyy>0.004505</iyy>
                <izz>0.008515</izz>
            </inertia>
        </inertial>

        <collision name="right_knee_actuator_collision">
            <geometry>
                <mesh>
					<uri>model://simplified_biped/meshes/actuator_scaled.stl</uri>
				</mesh>
            </geometry>
        </collision>

        <visual name="right_knee_actuator_visual">
            <pose> 0 0 0 0 0 0</pose>
            <geometry>
                <mesh>
					<uri>model://simplified_biped/meshes/actuator_scaled.stl</uri>
				</mesh>
            </geometry>
        </visual>
    </link>

    <link name="right_hip_axis_2">

        <self_collide>1</self_collide>
        <pose> 0.15 -0.12 1.26 1.570796327 0 0 </pose>
        
        <inertial>
            <mass>2.5</mass>
            <inertia>
                <ixx>0.004505</ixx>
                <iyy>0.004505</iyy>
                <izz>0.008515</izz>
            </inertia>
        </inertial>

        <collision name="right_hip_axis_2_collision">
            <geometry>
                <mesh>
					<uri>model://simplified_biped/meshes/actuator_scaled.stl</uri>
				</mesh>
            </geometry>
        </collision>

        <visual name="right_hip_axis_2_visual">
            <pose> 0 0 0 0 0 0</pose>
            <geometry>
                <mesh>
					<uri>model://simplified_biped/meshes/actuator_scaled.stl</uri>
				</mesh>
            </geometry>
        </visual>
    </link>

    <link name="right_hip_axis_3">

        <self_collide>1</self_collide>
        <pose> 0.15 0 1.377 0 0 0 </pose> <!--145mm from center of hip axis 2-->

        <inertial>
            <mass>2.5</mass>
            <inertia>
                <ixx>0.004505</ixx>
                <iyy>0.004505</iyy>
                <izz>0.008515</izz>
                <ixy>0</ixy>
                <ixz>0</ixz>
                <iyz>0</iyz>
            </inertia>
        </inertial>

        <collision name="right_hip_axis_3_collision">
            <geometry>
                <mesh>
					<uri>model://simplified_biped/meshes/actuator_scaled.stl</uri>
				</mesh>
            </geometry>
        </collision>

        <visual name="right_hip_axis_3_visual">
            <geometry>
                <mesh>
					<uri>model://simplified_biped/meshes/actuator_scaled.stl</uri>
				</mesh>
            </geometry>
        </visual>
    </link>

    <joint type="revolute" name="right_knee_lower_leg_joint">

        <pose> 0 0 0.205 0 0 0 </pose>

        <parent>right_knee</parent>

        <child>right_lower_leg</child>
        
        <axis>
            <xyz>1 0 0 </xyz>
            <limit>
                <lower>-2.5</lower>
                <upper>2.5</upper>
            </limit>
        </axis>
    </joint>

    <joint type="revolute" name="right_hip_axis_1_upper_leg_joint">

        <pose> 0 0 0.205 0 0 0 </pose>

        <parent>right_hip_axis_1</parent>

        <child>right_upper_leg</child>

        <axis>
            <xyz>1 0 0 </xyz>
            <limit>
                <lower>-0.7</lower>
                <upper>2.5</upper>
            </limit>
        </axis>
    </joint>

	<joint type="fixed" name="right_hip_axis_1_knee_actuator_joint">
        <pose> -0.145 0 0 0 -1.570796 0 </pose>

        <parent>right_hip_axis_1</parent>
        <child>right_knee_actuator</child>
    </joint>

	<joint type="revolute" name="right_hip_axis_2_hip_axis_1_joint">
        <pose> 0 -0.12 -0.05 0 0 0 </pose>

        <parent>right_hip_axis_2</parent>
        <child>right_hip_axis_1</child>

        <axis>
            <xyz> 0 1 0 </xyz>
            <limit>
                <lower>-2.5</lower>
                <upper>2.5</upper>
            </limit>
        </axis>
    </joint>

    <joint type="revolute" name="right_hip_axis_3_hip_axis_2_joint">
        <pose> 0 0.12 -0.117 0 0 0 </pose>

        <parent>right_hip_axis_3</parent>
        <child>right_hip_axis_2</child>

        <axis>
            <xyz> 0 1 0 </xyz>
            <limit>
                <lower>-1</lower>
                <upper>1</upper>
            </limit>
        </axis>
    </joint>

    <joint type="revolute" name="right_ankle_foot_base_joint">
        <pose> 0 0 0.03 0 0 0 </pose>

        <parent>right_ankle</parent>
        <child>right_foot_base</child>

        <axis>
            <xyz>1 0 0 </xyz>
            <limit>
                <lower>-1.57</lower>
                <upper>1.57</upper>
            </limit>
        </axis>
    </joint>

    <joint type="fixed" name="right_knee_upper_leg_joint">
        <pose>0 0 0 0 0 0 </pose>
        <parent>right_upper_leg</parent>
        <child>right_knee</child>
    </joint>

    <joint type="fixed" name="right_ankle_lower_leg_joint">
        <pose> 0 0 0 0 0 0 </pose>
        <parent>right_lower_leg</parent>
        <child>right_ankle</child>
    </joint>

	<joint type="fixed" name="right_torso_connection_joint">
        <pose> 0 0 0 0 0 0 </pose>
        <parent>torso_connection</parent>
        <child>right_hip_axis_3</child>
    </joint>
</model>
</sdf>
