<?xml version="1.0" ?>
<sdf version="1.6">
 
<model name="simplified_biped">
 
    <!-- One leg weighs approximately 3.22kg -->
    <!-- IMPORTANT: EVERY LINK IS OFFSET BY 0.065m TO BRING IT AS POSSIBLE TO THE GRONUD WITH THE NONZERO ANGLES SET BY THE PLUGIN CODE. TO REVERT, SIMPLY ADD 0.065 TO EVERY LINK HEIGHT -->
    <link name="torso_connection">
        <self_collide> 1 </self_collide>
 
        <pose> 0 0 1.115 0 0 0 </pose>
 
        <inertial>
            <mass>21.68</mass>
 
            <inertia>
                <ixx>0.15121</ixx>
                <iyy>0.6296</iyy>
                <izz>0.6881</izz>
            </inertia>
        </inertial>
 
        <collision name="torso_connection_collision">
            <geometry>
                <mesh>
	   		 		<uri>model://simplified_biped/meshes/torso_connection.stl</uri>
				</mesh>
            </geometry>
        </collision>
 
        <visual name="torso_connection_visual">
            <geometry>
                <mesh>
					<uri>model://simplified_biped/meshes/torso_connection.stl</uri>
				</mesh>
            </geometry>
        </visual>
    </link>
 
    <!--Left leg-->
    <link name="left_lower_leg">
 
        <self_collide>0</self_collide>
 
        <pose> -0.15 0 0.145 0 0 0 </pose>
 
            <inertial>
                <mass>0.5</mass>
                <inertia>
                    <ixx>0.003991</ixx>
                    <iyy>0.003991</iyy>
					<izz>0.0004689</izz>
                </inertia>
            </inertial>
 
            <collision name="left_base_collision">
                <geometry>
                    <mesh>
						<uri>model://simplified_biped/meshes/lower_leg_350mm.stl</uri>
					</mesh>
                </geometry>
            </collision>
 
            <visual name="left_base_visual">
                <geometry>
                    <mesh>
		   		 		<uri>model://simplified_biped/meshes/lower_leg_350mm.stl</uri>
					</mesh>
                </geometry>
            </visual>
    </link>
 
    <link name="left_knee">
 
        <self_collide>1</self_collide>
        <pose> -0.15 0 0.35 0 1.570796 0</pose>
 
        <inertial>
            <mass>0.05</mass>
            <inertia>
                <ixx>5e-05</ixx>
                <iyy>4e-05</iyy>
                <izz>4e-05</izz>
            </inertia>
        </inertial>
 
        <collision name="left_knee_collision">
            <geometry>
                <cylinder>
                    <radius>0.05</radius>
                    <length>0.06</length>
                </cylinder>
            </geometry>
        </collision>
 
        <visual name="left_knee_visual">
            <pose> 0 0 0 0 0 0</pose>
            <geometry>
                <cylinder>
                    <radius>0.05</radius>
                    <length>0.06</length>
                </cylinder>
            </geometry>
        </visual>
    </link>
 
    <link name="left_upper_leg">
 
        <self_collide>1</self_collide>
 
        <pose> -0.15 0 0.555 0 0 0 </pose> 
 
        <inertial>
            <mass>0.5</mass>
            <inertia>
                <ixx>0.003991</ixx>
                <iyy>0.003991</iyy>
                <izz>0.0004689</izz>
            </inertia>
        </inertial>

        <collision name="left_upper_leg_collision">
            <geometry>
                <mesh>
					<uri>model://simplified_biped/meshes/upper_leg_350mm.stl</uri>
				</mesh>
            </geometry>
        </collision>
 
        <visual name="left_upper_leg_visual">
            <geometry>
                <mesh>
					<uri>model://simplified_biped/meshes/upper_leg_350mm.stl</uri>
				</mesh>
            </geometry>
        </visual>
    </link>
 
    <link name="left_foot_base">
 
        <self_collide>0</self_collide>
        <pose> -0.15 0 -0.055 0 0 0</pose>
 
        <inertial>
            <mass>0.1</mass>
            <inertia>
                <ixx>0.000284</ixx>
                <iyy>5.6e-05</iyy>
                <izz>0.00032</izz>
            </inertia>
        </inertial>
 
        <collision name="left_foot_base_collision">
            <geometry>
                <box>
                    <size> 0.08 0.18 0.02</size>
                </box>
            </geometry>

            <surface>
                <friction>
                    <ode>
                        <mu>100</mu>
                        <mu2>100</mu2>
                        <slip1>0</slip1>
                        <slip2>0</slip2>
                    </ode>
                    <bullet>
                        <friction>100</friction>
                        <friction2>100</friction2>
                    </bullet>
                </friction>
                <contact>
                    <ode>
                        <min_depth>0.005</min_depth>
                    </ode>
                </contact>
            </surface>
        </collision>
 
        <visual name="left_foot_base_visual">
            <geometry>
                <box>
                    <size> 0.08 0.18 0.02</size>
                </box>
            </geometry>
        </visual>

        <sensor name='left_foot_contact' type='contact'>
            <plugin name="foot_contact_plugin" filename="./libfoot_contact_plugin.so"/>
            <contact>
                <collision>left_foot_base_collision</collision>
            </contact>
        </sensor>
    </link>
 
    <link name="left_ankle">
 
        <self_collide>1</self_collide>
        <pose> -0.15 0 -0.025 0 1.570796 0 </pose>
 
        <inertial>
            <mass>0.01</mass>
            <inertia>
                <ixx>0.000024</ixx>
                <iyy>0.000024</iyy>
                <izz>0.000004</izz>
            </inertia>
        </inertial>
 
        <collision name="left_ankle_collision">
            <geometry>
                <cylinder>
                    <radius>0.008</radius>
                    <length>0.06</length>
                </cylinder>
            </geometry>
        </collision>
 
        <visual name="left_ankle_visual">
            <geometry>
                <cylinder>
                    <radius>0.008</radius>
                    <length>0.06</length>
                </cylinder>
            </geometry>
        </visual>
    </link>
 
    <link name="left_hip_axis_1">
 
        <self_collide>1</self_collide>
        <pose> -0.15 0 0.76 0 1.570796 0 </pose>

        <inertial>
            <mass>1</mass>
            <inertia>
                <ixx>1.249e-03</ixx>
                <iyy>9.250e-04</iyy>
                <izz>9.250e-04</izz>
            </inertia>
        </inertial>
 
        <collision name="left_hip_axis_1_collision">
            <geometry>
                <cylinder>
                    <radius>0.05</radius>
                    <length>0.06</length>
                </cylinder>
            </geometry>
        </collision>
 
        <visual name="left_hip_axis_1_visual">
            <pose> 0 0 0 0 0 0</pose>
            <geometry>
                <cylinder>
                    <radius>0.05</radius>
                    <length>0.06</length>
                </cylinder>
            </geometry>
        </visual>
    </link>
 
    <link name="left_hip_axis_2">
 
        <self_collide>1</self_collide>
        <pose> -0.15 0 0.905 0 1.570796 1.570796 </pose>
 
        <inertial>
            <mass>1</mass>
            <inertia>
                <ixx>1.249e-03</ixx>
                <iyy>9.250e-04</iyy>
                <izz>9.250e-04</izz>
            </inertia>
        </inertial>
 
        <collision name="left_hip_axis_2_collision">
            <geometry>
                <cylinder>
                    <radius>0.05</radius>
                    <length>0.06</length>
                </cylinder>
            </geometry>
        </collision>
 
        <visual name="left_hip_axis_2_visual">
            <pose> 0 0 0 0 0 0</pose>
            <geometry>
                <cylinder>
                    <radius>0.05</radius>
                    <length>0.06</length>
                </cylinder>
            </geometry>
        </visual>
    </link>
 
    <link name="left_hip_axis_3">
 
        <self_collide>1</self_collide>
        <pose> -0.15 0 1.05 0 0 0 </pose> <!--145mm from center of hip axis 2-->
 
        <inertial>
            <mass>1</mass>
            <inertia>
                <ixx>1.249e-03</ixx>
                <iyy>9.250e-04</iyy>
                <izz>9.250e-04</izz>
            </inertia>
        </inertial>
 
        <collision name="left_hip_axis_3_collision">
            <geometry>
                <mesh>
					<uri>model://simplified_biped/meshes/actuator_scaled.stl</uri>
				</mesh>
            </geometry>
        </collision>
 
        <visual name="left_hip_axis_3_visual">
            <geometry>
                <mesh>
					<uri>model://simplified_biped/meshes/actuator_scaled.stl</uri>
				</mesh>
            </geometry>
        </visual>
    </link>
 
    <joint type="revolute" name="left_knee_lower_leg_joint">
 
        <pose> 0 0 0.205 0 0 0 </pose>
 
        <parent>left_knee</parent>
 
        <child>left_lower_leg</child>
 
        <axis>
            <xyz>1 0 0 </xyz>
            <limit>
                <lower>-2.5</lower>
                <upper>2.5</upper>
            </limit>
        </axis>
    </joint>
 
    <joint type="revolute" name="left_hip_axis_1_upper_leg_joint">
 
        <pose> 0 0 0.205 0 0 0 </pose>
 
        <parent>left_hip_axis_1</parent>
 
        <child>left_upper_leg</child>
 
        <axis>
            <xyz>1 0 0 </xyz>
            <limit>
                <lower>-2.5</lower>
                <upper>2.5</upper>
            </limit>
        </axis>
    </joint>
 
    <joint type="revolute" name="left_hip_axis_2_hip_axis_1_joint">
        <pose> -0.145 0 0 0 -1.570796 0 </pose>
 
        <parent>left_hip_axis_2</parent>
        <child>left_hip_axis_1</child>
 
        <axis>
            <xyz> 0 1 0 </xyz>
            <limit>
                <lower>-2.5</lower>
                <upper>2.5</upper>
            </limit>
        </axis>
    </joint>
 
    <joint type="revolute" name="left_hip_axis_3_hip_axis_2_joint">
        <pose> -0.145 0 0 0 -1.5707 0 </pose>
 
        <parent>left_hip_axis_3</parent>
        <child>left_hip_axis_2</child>
 
        <axis>
            <xyz> 0 0 1 </xyz>
            <limit>
                <lower>-1</lower>
                <upper>1</upper>
            </limit>
        </axis>
    </joint>
 
    <!--Change joint type back to revolute if actively driven ankle joint is needed-->
    <joint type="revolute" name="left_ankle_foot_base_joint">
        <pose> 0 0 0.03 0 0 0 </pose>
 
        <parent>left_ankle</parent>
        <child>left_foot_base</child>
        <axis>
            <xyz>1 0 0 </xyz>
            <limit>
                <lower>-1.57</lower>
                <upper>1.57</upper>
            </limit>
        </axis>
        <sensor name="left_foot_force_torque" type="force_torque">
            <plugin name="foot_force_plugin" filename="./libfoot_force_plugin.so"/>
            <update_rate>250</update_rate>
        </sensor>
    </joint>
 
    <joint type="fixed" name="left_torso_connection_joint">
        <pose> 0 0 0 0 0 0 </pose>
        <parent>torso_connection</parent>
        <child>left_hip_axis_3</child>
    </joint>
 
    <joint type="fixed" name="left_upper_leg_knee_joint">
        <pose> 0 0 0 0 0 0 </pose>
        <parent>left_upper_leg</parent>
        <child>left_knee</child>
    </joint>
 
    <joint type="fixed" name="left_lower_leg_ankle_joint">
        <pose>0 0 0 0 0 0</pose>
        <parent>left_lower_leg</parent>
        <child>left_ankle</child>
    </joint>
 
    <!--right leg-->
    <link name="right_lower_leg">
 
        <self_collide>0</self_collide>
 
        <pose> 0.15 0 0.145 0 0 0 </pose>
 
            <inertial>
                <mass>0.5</mass>
                <inertia>
                    <ixx>0.003991</ixx>
                    <iyy>0.003991</iyy>
					<izz>0.0004689</izz>
                </inertia>
            </inertial>
 
            <collision name="right_base_collision">
                <geometry>
                    <mesh>
						<uri>model://simplified_biped/meshes/lower_leg_350mm.stl</uri>
					</mesh>
                </geometry>
            </collision>
 
            <visual name="right_base_visual">
                <geometry>
                    <mesh>
		   		 		<uri>model://simplified_biped/meshes/lower_leg_350mm.stl</uri>
					</mesh>
                </geometry>
            </visual>
    </link>
 
    <link name="right_knee">
 
        <self_collide>1</self_collide>
        <pose> 0.15 0 0.35 0 1.570796 0</pose>
 
        <inertial>
            <mass>0.05</mass>
            <inertia>
                <ixx>5e-05</ixx>
                <iyy>4e-05</iyy>
                <izz>4e-05</izz>
            </inertia>
        </inertial>
 
        <collision name="right_knee_collision">
            <geometry>
                <cylinder>
                    <radius>0.05</radius>
                    <length>0.06</length>
                </cylinder>
            </geometry>
        </collision>
 
        <visual name="right_knee_visual">
            <pose> 0 0 0 0 0 0</pose>
            <geometry>
                <cylinder>
                    <radius>0.05</radius>
                    <length>0.06</length>
                </cylinder>
            </geometry>
        </visual>
    </link>
 
    <link name="right_upper_leg">
 
        <self_collide>1</self_collide>
 
        <pose> 0.15 0 0.555 0 0 0 </pose> 
 
            <inertial>
                <mass>0.5</mass>
                <inertia>
                    <ixx>0.003991</ixx>
                    <iyy>0.003991</iyy>
					<izz>0.0004689</izz>
                </inertia>
            </inertial>
 
        <collision name="right_upper_leg_collision">
            <geometry>
                <mesh>
					<uri>model://simplified_biped/meshes/upper_leg_350mm.stl</uri>
				</mesh>
            </geometry>
        </collision>
 
        <visual name="right_upper_leg_visual">
            <geometry>
                <mesh>
					<uri>model://simplified_biped/meshes/upper_leg_350mm.stl</uri>
				</mesh>
            </geometry>
        </visual>
    </link>
 
    <link name="right_foot_base">
 
        <self_collide>0</self_collide>
        <pose> 0.15 0 -0.055 0 0 0</pose>
 
        <inertial>
            <mass>0.1</mass>
            <inertia>
                <ixx>0.000284</ixx>
                <iyy>5.6e-05</iyy>
                <izz>0.00032</izz>
            </inertia>
        </inertial>
 
        <collision name="right_foot_base_collision">
            <geometry>
                <box>
                    <size> 0.08 0.18 0.02</size>
                </box>
            </geometry>

            <surface>
                <friction>
                    <ode>
                        <mu>100</mu>
                        <mu2>100</mu2>
                        <slip1>0</slip1>
                        <slip2>0</slip2>
                    </ode>
                    <bullet>
                        <friction>100</friction>
                        <friction2>100</friction2>
                    </bullet>
                </friction>
                <contact>
                    <ode>
                        <min_depth>0.005</min_depth>
                    </ode>
                </contact>
            </surface>
        </collision>
 
        <visual name="right_foot_base_visual">
            <geometry>
                <box>
                    <size> 0.08 0.18 0.02</size>
                </box>
            </geometry>
        </visual>

        <sensor name='right_foot_contact' type='contact'>
            <plugin name="foot_contact_plugin" filename="./libfoot_contact_plugin.so"/>
            <contact>
                <collision>right_foot_base_collision</collision>
            </contact>
        </sensor>
    </link>
 
    <link name="right_ankle">
 
        <self_collide>1</self_collide>
        <pose> 0.15 0 -0.025 0 1.570796 0 </pose>
 
        <inertial>
            <mass>0.01</mass>
            <inertia>
                <ixx>0.000024</ixx>
                <iyy>0.000024</iyy>
                <izz>0.000004</izz>
            </inertia>
        </inertial>
 
        <collision name="right_ankle_collision">
            <geometry>
                <cylinder>
                    <radius>0.008</radius>
                    <length>0.06</length>
                </cylinder>
            </geometry>
        </collision>
 
        <visual name="right_ankle_visual">
            <geometry>
                <cylinder>
                    <radius>0.008</radius>
                    <length>0.06</length>
                </cylinder>
            </geometry>
        </visual>
    </link>
 
    <link name="right_hip_axis_1">
 
        <self_collide>1</self_collide>
        <pose> 0.15 0 0.76 0 1.570796 0 </pose>
 
        <inertial>
            <mass>1</mass>
            <inertia>
                <ixx>1.249e-03</ixx>
                <iyy>9.250e-04</iyy>
                <izz>9.250e-04</izz>
            </inertia>
        </inertial>
 
        <collision name="right_hip_axis_1_collision">
            <geometry>
                <cylinder>
                    <radius>0.05</radius>
                    <length>0.06</length>
                </cylinder>
            </geometry>
        </collision>
 
        <visual name="right_hip_axis_1_visual">
            <pose> 0 0 0 0 0 0</pose>
            <geometry>
                <cylinder>
                    <radius>0.05</radius>
                    <length>0.06</length>
                </cylinder>
            </geometry>
        </visual>
    </link>
 
    <link name="right_hip_axis_2">
 
        <self_collide>1</self_collide>
        <pose> 0.15 0 0.905 0 1.570796 1.570796 </pose>
 
        <inertial>
            <mass>1</mass>
            <inertia>
                <ixx>1.249e-03</ixx>
                <iyy>9.250e-04</iyy>
                <izz>9.250e-04</izz>
            </inertia>
        </inertial>
 
        <collision name="right_hip_axis_2_collision">
            <geometry>
                <cylinder>
                    <radius>0.05</radius>
                    <length>0.06</length>
                </cylinder>
            </geometry>
        </collision>
 
        <visual name="right_hip_axis_2_visual">
            <pose> 0 0 0 0 0 0</pose>
            <geometry>
                <cylinder>
                    <radius>0.05</radius>
                    <length>0.06</length>
                </cylinder>
            </geometry>
        </visual>
    </link>
 
    <link name="right_hip_axis_3">
 
        <self_collide>1</self_collide>
        <pose> 0.15 0 1.05 0 0 0 </pose> <!--145mm from center of hip axis 2-->
 
        <inertial>
            <mass>1</mass>
            <inertia>
                <ixx>1.249e-03</ixx>
                <iyy>9.250e-04</iyy>
                <izz>9.250e-04</izz>
            </inertia>
        </inertial>
 
        <collision name="right_hip_axis_3_collision">
            <geometry>
                <mesh>
					<uri>model://simplified_biped/meshes/actuator_scaled.stl</uri>
				</mesh>
            </geometry>
        </collision>
 
        <visual name="right_hip_axis_3_visual">
            <geometry>
                <mesh>
					<uri>model://simplified_biped/meshes/actuator_scaled.stl</uri>
				</mesh>
            </geometry>
        </visual>
    </link>
 
    <joint type="revolute" name="right_knee_lower_leg_joint">
 
        <pose> 0 0 0.205 0 0 0 </pose>
 
        <parent>right_knee</parent>
 
        <child>right_lower_leg</child>
 
        <axis>
            <xyz>1 0 0 </xyz>
            <limit>
                <lower>-2.5</lower>
                <upper>2.5</upper>
            </limit>
        </axis>
    </joint>
 
    <joint type="revolute" name="right_hip_axis_1_upper_leg_joint">
 
        <pose> 0 0 0.205 0 0 0 </pose>
 
        <parent>right_hip_axis_1</parent>
 
        <child>right_upper_leg</child>
 
        <axis>
            <xyz>1 0 0 </xyz>
            <limit>
                <lower>-2.5</lower>
                <upper>2.5</upper>
            </limit>
        </axis>
    </joint>
 
    <joint type="revolute" name="right_hip_axis_2_hip_axis_1_joint">
        <pose> -0.145 0 0 0 -1.570796 0 </pose>
 
        <parent>right_hip_axis_2</parent>
        <child>right_hip_axis_1</child>
 
        <axis>
            <xyz> 0 1 0 </xyz>
            <limit>
                <lower>-2.5</lower>
                <upper>2.5</upper>
            </limit>
        </axis>
    </joint>
 
    <joint type="revolute" name="right_hip_axis_3_hip_axis_2_joint">
        <pose> -0.145 0 0 0 -1.5707 0 </pose>
 
        <parent>right_hip_axis_3</parent>
        <child>right_hip_axis_2</child>
 
        <axis>
            <xyz> 0 0 1 </xyz>
            <limit>
                <lower>-1</lower>
                <upper>1</upper>
            </limit>
        </axis>
    </joint>
 
    <!--Change joint type back to revolute if actively driven ankle joint is needed-->
    <joint type="revolute" name="right_ankle_foot_base_joint">
        <pose> 0 0 0.03 0 0 0 </pose>
 
        <parent>right_ankle</parent>
        <child>right_foot_base</child>
        <axis>
            <xyz>1 0 0 </xyz>
            <limit>
                <lower>-1.57</lower>
                <upper>1.57</upper>
            </limit>
        </axis>
        <sensor name="right_foot_force_torque" type="force_torque">
            <plugin name="foot_force_plugin" filename="./libfoot_force_plugin.so"/>
            <update_rate>250</update_rate>
        </sensor>
    </joint>
 
    <joint type="fixed" name="right_torso_connection_joint">
        <pose> 0 0 0 0 0 0 </pose>
        <parent>torso_connection</parent>
        <child>right_hip_axis_3</child>
    </joint>
 
    <joint type="fixed" name="right_upper_leg_knee_joint">
        <pose> 0 0 0 0 0 0 </pose>
        <parent>right_upper_leg</parent>
        <child>right_knee</child>
    </joint>
 
    <joint type="fixed" name="right_lower_leg_ankle_joint">
        <pose>0 0 0 0 0 0</pose>
        <parent>right_lower_leg</parent>
        <child>right_ankle</child>
    </joint>
</model>
</sdf>