<?xml version="1.0" ?>
<sdf version="1.5">

<model name="simplified_biped">

    <link name="torso_connection">
        <self_collide> 1 </self_collide>

        <pose> 0 0 1.115 0 0 0 </pose>

        <inertial>
            <mass>10</mass>

            <inertia>
                <ixx>0.03</ixx>
                <iyy>0.166</iyy>
                <izz>0.175</izz>
                <ixy>0</ixy>
                <ixz>0</ixz>
                <iyz>0</iyz>
            </inertia>
        </inertial>

        <collision name="torso_connection_collision">
            <geometry>
                <box>
                    <size> 0.44 0.15 0.10 </size>
                </box>
            </geometry>
        </collision>

        <visual name="torso_connection_visual">
            <geometry>
                <box>
                    <size> 0.44 0.15 0.10 </size>
                </box>
            </geometry>
        </visual>
    </link>

    <!--Left leg-->
    <link name="left_lower_leg">

        <self_collide>1</self_collide>

        <pose> 0.15 0 0.21 0 0 0 </pose>

            <inertial>
                <mass>0.05</mass>
                <inertia>
                    <ixx>0.00038</ixx>
                    <izz>0.00003</izz>
                    <iyy>0.00038</iyy>
                    <ixy>0</ixy>
                    <ixz>0</ixz>
                    <iyz>0</iyz>
                </inertia>
            </inertial>
            
            <collision name="left_base_collision">
                <geometry>
                    <box>
                        <size> 0.06 0.06 0.3 </size>
                    </box>
                </geometry>
            </collision>

            <visual name="left_base_visual">
                <geometry>
                    <box>
                        <size> 0.06 0.06 0.3 </size>
                    </box>
                </geometry>
            </visual>
    </link>

    <link name="left_knee">

        <self_collide>1</self_collide>
        <pose> 0.15 0 0.415 0 1.570796 0</pose>

        <inertial>
            <mass>0.05</mass>
            <inertia>
                <ixx>0.00005</ixx>
                <iyy>0.00005</iyy>
                <izz>0.00007</izz>
                <ixy>0</ixy>
                <ixz>0</ixz>
                <iyz>0</iyz>
            </inertia>
        </inertial>

        <collision name="left_knee_collision">
            <geometry>
                <cylinder>
                    <radius>0.05</radius>
                    <length>0.06</length>
                </cylinder>
            </geometry>
        </collision>

        <visual name="left_knee_visual">
            <pose> 0 0 0 0 0 0</pose>
            <geometry>
                <cylinder>
                    <radius>0.05</radius>
                    <length>0.06</length>
                </cylinder>
            </geometry>
        </visual>
    </link>

    <link name="left_upper_leg">

        <self_collide>1</self_collide>

        <pose> 0.15 0 0.62 0 0 0 </pose> 

        <inertial>
            <mass>0.05</mass>
            <inertia>
                <ixx>0.00038</ixx>
                <iyy>0.00038</iyy>
                <izz>0.00003</izz>
                <ixy>0</ixy>
                <ixz>0</ixz>
                <iyz>0</iyz>
            </inertia>
        </inertial>

        <!-- To make them perfectly stacked: 0.65m height-->
        
        <collision name="left_upper_leg_collision">
            <geometry>
                <box>
                    <size> 0.06 0.06 0.3 </size>
                </box>
            </geometry>
        </collision>

        <visual name="left_upper_leg_visual">
            <geometry>
                <box>
                    <size> 0.06 0.06 0.3 </size>
                </box>
            </geometry>
        </visual>
    </link>

    <link name="left_foot_base">

        <self_collide>1</self_collide>
        <pose> 0.15 0 0.01 0 0 0</pose>

        <inertial>
            <mass>0.01</mass>
            <inertia>
                <ixx>0.000025</ixx>
                <iyy>0.0000045</iyy>
                <izz>0.000028</izz>
                <ixy>0</ixy>
                <ixz>0</ixz>
                <iyz>0</iyz>
            </inertia>
        </inertial>

        <collision name="left_foot_base_collision">
            <geometry>
                <box>
                    <size> 0.08 0.18 0.02</size>
                </box>
            </geometry>
        </collision>

        <visual name="left_foot_base_visual">
            <geometry>
                <box>
                    <size> 0.08 0.18 0.02</size>
                </box>
            </geometry>
        </visual>
    </link>

    <link name="left_ankle">

        <self_collide>1</self_collide>
        <pose> 0.15 0 0.04 0 1.570796 0 </pose>

        <inertial>
            <mass>0.03</mass>
            <inertia>
                <ixx>0.0000048</ixx>
                <iyy>0.0000048</iyy>
                <izz>0.0000008</izz>
                <ixy>0</ixy>
                <ixz>0</ixz>
                <iyz>0</iyz>
            </inertia>
        </inertial>

        <collision name="left_ankle_collision">
            <geometry>
                <cylinder>
                    <radius>0.008</radius>
                    <length>0.06</length>
                </cylinder>
            </geometry>
        </collision>

        <visual name="left_ankle_visual">
            <geometry>
                <cylinder>
                    <radius>0.008</radius>
                    <length>0.06</length>
                </cylinder>
            </geometry>
        </visual>
    </link>

    <link name="left_hip_axis_1">

        <self_collide>1</self_collide>
        <pose> 0.15 0 0.825 0 1.570796 0 </pose>

        <inertial>
            <mass>0.05</mass>
            <inertia>
                <ixx>0.00005</ixx>
                <iyy>0.00005</iyy>
                <izz>0.00007</izz>
                <ixy>0</ixy>
                <ixz>0</ixz>
                <iyz>0</iyz>
            </inertia>
        </inertial>

        <collision name="left_hip_axis_1_collision">
            <geometry>
                <cylinder>
                    <radius>0.05</radius>
                    <length>0.06</length>
                </cylinder>
            </geometry>
        </collision>

        <visual name="left_hip_axis_1_visual">
            <pose> 0 0 0 0 0 0</pose>
            <geometry>
                <cylinder>
                    <radius>0.05</radius>
                    <length>0.06</length>
                </cylinder>
            </geometry>
        </visual>
    </link>

    <link name="left_hip_axis_2">

        <self_collide>1</self_collide>
        <pose> 0.15 0 0.97 0 1.570796 1.570796 </pose>
        
        <inertial>
            <mass>0.05</mass>
            <inertia>
                <ixx>0.00005</ixx>
                <iyy>0.00005</iyy>
                <izz>0.00007</izz>
                <ixy>0</ixy>
                <ixz>0</ixz>
                <iyz>0</iyz>
            </inertia>
        </inertial>

        <collision name="left_hip_axis_2_collision">
            <geometry>
                <cylinder>
                    <radius>0.05</radius>
                    <length>0.06</length>
                </cylinder>
            </geometry>
        </collision>

        <visual name="left_hip_axis_2_visual">
            <pose> 0 0 0 0 0 0</pose>
            <geometry>
                <cylinder>
                    <radius>0.05</radius>
                    <length>0.06</length>
                </cylinder>
            </geometry>
        </visual>
    </link>

    <link name="left_hip_axis_3">

        <self_collide>1</self_collide>
        <pose> 0.15 0 1.115 0 0 0 </pose> <!--145mm from center of hip axis 2-->

        <inertial>
            <mass>0.05</mass>
            <inertia>
                <ixx>0.00005</ixx>
                <iyy>0.00005</iyy>
                <izz>0.00007</izz>
                <ixy>0</ixy>
                <ixz>0</ixz>
                <iyz>0</iyz>
            </inertia>
        </inertial>

        <collision name="left_hip_axis_3_collision">
            <geometry>
                <cylinder>
                    <radius>0.05</radius>
                    <length>0.06</length>
                </cylinder>
            </geometry>
        </collision>

        <visual name="left_hip_axis_3_visual">
            <geometry>
                <cylinder>
                    <radius>0.05</radius>
                    <length>0.06</length>
                </cylinder>
            </geometry>
        </visual>
    </link>

    <joint type="revolute" name="left_knee_lower_leg_joint">

        <pose> 0 0 0.205 0 0 0 </pose>

        <parent>left_knee</parent>

        <child>left_lower_leg</child>
        
        <axis>
            <xyz>1 0 0 </xyz>
        </axis>
    </joint>

    <joint type="revolute" name="left_hip_axis_1_upper_leg_joint">

        <pose> 0 0 0.205 0 0 0 </pose>

        <parent>left_hip_axis_1</parent>

        <child>left_upper_leg</child>

        <axis>
            <xyz>1 0 0 </xyz>
        </axis>
    </joint>

    <joint type="revolute" name="left_hip_axis_2_hip_axis_1_joint">
        <pose> -0.145 0 0 0 -1.570796 0 </pose>

        <parent>left_hip_axis_2</parent>
        <child>left_hip_axis_1</child>

        <axis>
            <xyz> 0 1 0 </xyz>
        </axis>
    </joint>

    <joint type="revolute" name="left_hip_axis_3_hip_axis_2_joint">
        <pose> -0.145 0 0 0 -1.5707 0 </pose>

        <parent>left_hip_axis_3</parent>
        <child>left_hip_axis_2</child>

        <axis>
            <xyz> 0 0 1 </xyz>
        </axis>
    </joint>
    
    <!--Change joint type back to revolute if actively driven ankle joint is needed-->
    <joint type="fixed" name="left_ankle_foot_base_joint">
        <pose> 0 0 0.03 0 0 0 </pose>

        <parent>left_ankle</parent>
        <child>left_foot_base</child>
        <limit>
            <lower>0</lower>
            <upper>0</upper>
        </limit>
        <axis>
            <xyz>1 0 0 </xyz>
        </axis>
    </joint>

    <joint type="fixed" name="left_knee_upper_leg_joint">
        <pose>0 0 0 0 0 0 </pose>
        <parent>left_upper_leg</parent>
        <child>left_knee</child>
    </joint>

    <joint type="fixed" name="left_ankle_lower_leg_joint">
        <pose> 0 0 0 0 0 0 </pose>
        <parent>left_lower_leg</parent>
        <child>left_ankle</child>
    </joint>

    <!--Right leg-->

    <link name="right_lower_leg">

        <self_collide>1</self_collide>

        <pose> -0.15 0 0.21 0 0 0 </pose>

            <inertial>
                <mass>0.05</mass>
                <inertia>
                    <ixx>0.00038</ixx>
                    <izz>0.00003</izz>
                    <iyy>0.00038</iyy>
                    <ixy>0</ixy>
                    <ixz>0</ixz>
                    <iyz>0</iyz>
                </inertia>
            </inertial>
            
            <collision name="right_base_collision">
                <geometry>
                    <box>
                        <size> 0.06 0.06 0.3 </size>
                    </box>
                </geometry>
            </collision>

            <visual name="right_base_visual">
                <geometry>
                    <box>
                        <size> 0.06 0.06 0.3 </size>
                    </box>
                </geometry>
            </visual>
    </link>

    <link name="right_knee">

        <self_collide>1</self_collide>
        <pose> -0.15 0 0.415 0 1.570796 0</pose>

        <inertial>
            <mass>0.05</mass>
            <inertia>
                <ixx>0.00005</ixx>
                <iyy>0.00005</iyy>
                <izz>0.00007</izz>
                <ixy>0</ixy>
                <ixz>0</ixz>
                <iyz>0</iyz>
            </inertia>
        </inertial>

        <collision name="right_knee_collision">
            <geometry>
                <cylinder>
                    <radius>0.05</radius>
                    <length>0.06</length>
                </cylinder>
            </geometry>
        </collision>

        <visual name="right_knee_visual">
            <pose> 0 0 0 0 0 0</pose>
            <geometry>
                <cylinder>
                    <radius>0.05</radius>
                    <length>0.06</length>
                </cylinder>
            </geometry>
        </visual>
    </link>

    <link name="right_upper_leg">

        <self_collide>1</self_collide>

        <pose> -0.15 0 0.62 0 0 0 </pose> 

        <inertial>
            <mass>0.05</mass>
            <inertia>
                <ixx>0.00038</ixx>
                <iyy>0.00038</iyy>
                <izz>0.00003</izz>
                <ixy>0</ixy>
                <ixz>0</ixz>
                <iyz>0</iyz>
            </inertia>
        </inertial>

        <!-- To make them perfectly stacked: 0.65m height-->
        
        <collision name="right_upper_leg_collision">
            <geometry>
                <box>
                    <size> 0.06 0.06 0.3 </size>
                </box>
            </geometry>
        </collision>

        <visual name="right_upper_leg_visual">
            <geometry>
                <box>
                    <size> 0.06 0.06 0.3 </size>
                </box>
            </geometry>
        </visual>
    </link>

    <link name="right_foot_base">

        <self_collide>1</self_collide>
        <pose> -0.15 0 0.01 0 0 0</pose>

        <inertial>
            <mass>0.01</mass>
            <inertia>
                <ixx>0.000025</ixx>
                <iyy>0.0000045</iyy>
                <izz>0.000028</izz>
                <ixy>0</ixy>
                <ixz>0</ixz>
                <iyz>0</iyz>
            </inertia>
        </inertial>

        <collision name="right_foot_base_collision">
            <geometry>
                <box>
                    <size> 0.08 0.18 0.02</size>
                </box>
            </geometry>
        </collision>

        <visual name="right_foot_base_visual">
            <geometry>
                <box>
                    <size> 0.08 0.18 0.02</size>
                </box>
            </geometry>
        </visual>
    </link>

    <link name="right_ankle">

        <self_collide>1</self_collide>
        <pose> -0.15 0 0.04 0 1.570796 0 </pose>

        <inertial>
            <mass>0.03</mass>
            <inertia>
                <ixx>0.0000048</ixx>
                <iyy>0.0000048</iyy>
                <izz>0.0000008</izz>
                <ixy>0</ixy>
                <ixz>0</ixz>
                <iyz>0</iyz>
            </inertia>
        </inertial>

        <collision name="right_ankle_collision">
            <geometry>
                <cylinder>
                    <radius>0.008</radius>
                    <length>0.06</length>
                </cylinder>
            </geometry>
        </collision>

        <visual name="right_ankle_visual">
            <geometry>
                <cylinder>
                    <radius>0.008</radius>
                    <length>0.06</length>
                </cylinder>
            </geometry>
        </visual>
    </link>

    <link name="right_hip_axis_1">

        <self_collide>1</self_collide>
        <pose> -0.15 0 0.825 0 1.570796 0 </pose>

        <inertial>
            <mass>0.05</mass>
            <inertia>
                <ixx>0.00005</ixx>
                <iyy>0.00005</iyy>
                <izz>0.00007</izz>
                <ixy>0</ixy>
                <ixz>0</ixz>
                <iyz>0</iyz>
            </inertia>
        </inertial>

        <collision name="right_hip_axis_1_collision">
            <geometry>
                <cylinder>
                    <radius>0.05</radius>
                    <length>0.06</length>
                </cylinder>
            </geometry>
        </collision>

        <visual name="right_hip_axis_1_visual">
            <pose> 0 0 0 0 0 0</pose>
            <geometry>
                <cylinder>
                    <radius>0.05</radius>
                    <length>0.06</length>
                </cylinder>
            </geometry>
        </visual>
    </link>

    <link name="right_hip_axis_2">

        <self_collide>1</self_collide>
        <pose> -0.15 0 0.97 0 1.570796 1.570796 </pose>
        
        <inertial>
            <mass>0.05</mass>
            <inertia>
                <ixx>0.00005</ixx>
                <iyy>0.00005</iyy>
                <izz>0.00007</izz>
                <ixy>0</ixy>
                <ixz>0</ixz>
                <iyz>0</iyz>
            </inertia>
        </inertial>

        <collision name="right_hip_axis_2_collision">
            <geometry>
                <cylinder>
                    <radius>0.05</radius>
                    <length>0.06</length>
                </cylinder>
            </geometry>
        </collision>

        <visual name="right_hip_axis_2_visual">
            <pose> 0 0 0 0 0 0</pose>
            <geometry>
                <cylinder>
                    <radius>0.05</radius>
                    <length>0.06</length>
                </cylinder>
            </geometry>
        </visual>
    </link>

    <link name="right_hip_axis_3">

        <self_collide>1</self_collide>
        <pose> -0.15 0 1.115 0 0 0 </pose> <!--145mm from center of hip axis 2-->

        <inertial>
            <mass>0.05</mass>
            <inertia>
                <ixx>0.00005</ixx>
                <iyy>0.00005</iyy>
                <izz>0.00007</izz>
                <ixy>0</ixy>
                <ixz>0</ixz>
                <iyz>0</iyz>
            </inertia>
        </inertial>

        <collision name="right_hip_axis_3_collision">
            <geometry>
                <cylinder>
                    <radius>0.05</radius>
                    <length>0.06</length>
                </cylinder>
            </geometry>
        </collision>

        <visual name="right_hip_axis_3_visual">
            <geometry>
                <cylinder>
                    <radius>0.05</radius>
                    <length>0.06</length>
                </cylinder>
            </geometry>
        </visual>
    </link>

    <joint type="revolute" name="right_knee_lower_leg_joint">

        <pose> 0 0 0.205 0 0 0 </pose>

        <parent>right_knee</parent>

        <child>right_lower_leg</child>
        
        <axis>
            <xyz>1 0 0 </xyz>
        </axis>
    </joint>

    <joint type="revolute" name="right_hip_axis_1_upper_leg_joint">

        <pose> 0 0 0.205 0 0 0 </pose>

        <parent>right_hip_axis_1</parent>

        <child>right_upper_leg</child>

        <axis>
            <xyz>1 0 0 </xyz>
        </axis>
    </joint>

    <joint type="revolute" name="right_hip_axis_2_hip_axis_1_joint">
        <pose> -0.145 0 0 0 -1.570796 0 </pose>

        <parent>right_hip_axis_2</parent>
        <child>right_hip_axis_1</child>

        <axis>
            <xyz> 0 1 0 </xyz>
        </axis>
    </joint>

    <joint type="revolute" name="right_hip_axis_3_hip_axis_2_joint">
        <pose> -0.145 0 0 0 -1.5707 0 </pose>

        <parent>right_hip_axis_3</parent>
        <child>right_hip_axis_2</child>

        <axis>
            <xyz> 0 0 1 </xyz>
        </axis>
    </joint>
    <!--Change joint type back to revolute if actively driven ankle joint is needed-->
    <joint type="fixed" name="right_ankle_foot_base_joint">
        <pose> 0 0 0.03 0 0 0 </pose>

        <parent>right_ankle</parent>
        <child>right_foot_base</child>
        <limit>
            <lower>0</lower>
            <upper>0</upper>
        </limit>
        <axis>
            <xyz>1 0 0 </xyz>
        </axis>
    </joint>


    <joint type="fixed" name="right_knee_upper_leg_joint">
        <pose>0 0 0 0 0 0 </pose>
        <parent>right_upper_leg</parent>
        <child>right_knee</child>
    </joint>

    <joint type="fixed" name="right_ankle_lower_leg_joint">
        <pose> 0 0 0 0 0 0 </pose>
        <parent>right_lower_leg</parent>
        <child>right_ankle</child>
    </joint>

    <joint type="fixed" name="left_torso_connection_joint">
        <pose> 0 0 0 0 0 0 </pose>
        <parent>torso_connection</parent>
        <child>left_hip_axis_3</child>
    </joint>

    <joint type="fixed" name="right_torso_connection_joint">
        <pose> 0 0 0 0 0 0 </pose>
        <parent>torso_connection</parent>
        <child>right_hip_axis_3</child>
    </joint>

</model>
</sdf>