<?xml version="1.0" ?>
<sdf version="1.5">

<model name="simplified_biped">
    <link name="hanging_thing">
        <self_collide> 1 </self_collide>

        <pose> 0 0 1.7 0 0 0 </pose>

        <inertial>
            <mass>100</mass>

            <inertia>
                <ixx>0.3</ixx>
                <iyy>166</iyy>
                <izz>175</izz>
                <ixy>0</ixy>
                <ixz>0</ixz>
                <iyz>0</iyz>
            </inertia>
        </inertial>

        <collision name="torso_connection_collision">
            <geometry>
                <box>
                    <size> 0.80 0.3 0.1 </size>
                </box>
            </geometry>
        </collision>

        <visual name="torso_connection_visual">
            <geometry>
                <box>
                    <size> 0.80 0.3 0.1 </size>
                </box>
            </geometry>
        </visual>
    </link>

    <link name="rod_1">
        <self_collide> 1 </self_collide>

        <pose> 1 0 0.5 1.57 0 0 </pose>

        <inertial>
            <mass>100</mass>

            <inertia>
                <ixx>0.3</ixx>
                <iyy>166</iyy>
                <izz>175</izz>
                <ixy>0</ixy>
                <ixz>0</ixz>
                <iyz>0</iyz>
            </inertia>
        </inertial>

        <collision name="rod_1_collision">
            <geometry>
                <box>
                    <size> 0.15 1 0.15 </size>
                </box>
            </geometry>
        </collision>

        <visual name="rod_1_visual">
            <geometry>
                <box>
                    <size> 0.15 1 0.15 </size>
                </box>
            </geometry>
        </visual>
    </link>

    <link name="rod_2">
        <self_collide> 1 </self_collide>

        <pose> -1 0 0.5 1.57 0 0 </pose>

        <inertial>
            <mass>100</mass>

            <inertia>
                <ixx>0.3</ixx>
                <iyy>166</iyy>
                <izz>175</izz>
                <ixy>0</ixy>
                <ixz>0</ixz>
                <iyz>0</iyz>
            </inertia>
        </inertial>

        <collision name="rod_2_collision">
            <geometry>
                <box>
                    <size> 0.15 1 0.15 </size>
                </box>
            </geometry>
        </collision>

        <visual name="rod_2_visual">
            <geometry>
                <box>
                    <size> 0.15 1 0.15 </size>
                </box>
            </geometry>
        </visual>
    </link>

    <link name="rod_3">
        <self_collide> 1 </self_collide>

        <pose> 0 1 0.5 1.57 0 0 </pose>

        <inertial>
            <mass>100</mass>

            <inertia>
                <ixx>0.3</ixx>
                <iyy>166</iyy>
                <izz>175</izz>
                <ixy>0</ixy>
                <ixz>0</ixz>
                <iyz>0</iyz>
            </inertia>
        </inertial>

        <collision name="rod_3_collision">
            <geometry>
                <box>
                    <size> 0.15 1 0.15 </size>
                </box>
            </geometry>
        </collision>

        <visual name="rod_3_visual">
            <geometry>
                <box>
                    <size> 0.15 1 0.15 </size>
                </box>
            </geometry>
        </visual>
    </link>

    <link name="rod_4">
        <self_collide> 1 </self_collide>

        <pose> 0 -1 0.5 1.57 0 0 </pose>

        <inertial>
            <mass>100</mass>

            <inertia>
                <ixx>0.3</ixx>
                <iyy>166</iyy>
                <izz>175</izz>
                <ixy>0</ixy>
                <ixz>0</ixz>
                <iyz>0</iyz>
            </inertia>
        </inertial>

        <collision name="rod_4_collision">
            <geometry>
                <box>
                    <size> 0.15 1 0.15 </size>
                </box>
            </geometry>
        </collision>

        <visual name="rod_4_visual">
            <geometry>
                <box>
                    <size> 0.15 1 0.15 </size>
                </box>
            </geometry>
        </visual>
    </link>

    <joint name="temp_joint_1" type="fixed">
        <parent>hanging_thing</parent>
        <child>torso_connection</child>
    </joint>

    <joint name="temp_joint_2" type="fixed">
        <parent>rod_1</parent>
        <child>hanging_thing</child>
    </joint>

    <joint name="temp_joint_3" type="fixed">
        <parent>rod_2</parent>
        <child>hanging_thing</child>
    </joint>

    <joint name="temp_joint_4" type="fixed">
        <parent>rod_3</parent>
        <child>hanging_thing</child>
    </joint>

    <joint name="temp_joint_5" type="fixed">
        <parent>rod_4</parent>
        <child>hanging_thing</child>
    </joint>
    
    <link name="torso_connection">
        <self_collide> 1 </self_collide>

        <pose> 0 0 1.48 0 0 0 </pose>

        <inertial>
            <mass>10</mass>

            <inertia>
                <ixx>0.03</ixx>
                <iyy>0.166</iyy>
                <izz>0.175</izz>
                <ixy>0</ixy>
                <ixz>0</ixz>
                <iyz>0</iyz>
            </inertia>
        </inertial>

        <collision name="torso_connection_collision">
            <geometry>
                <mesh>
	   		 		<uri>model://simplified_biped/meshes/torso_connection.stl</uri>
				</mesh>
            </geometry>
        </collision>

        <visual name="torso_connection_visual">
            <geometry>
                <mesh>
					<uri>model://simplified_biped/meshes/torso_connection.stl</uri>
				</mesh>
            </geometry>
        </visual>
    </link>

    <!--Left leg-->
    <link name="left_lower_leg">

        <self_collide>1</self_collide>

        <pose> 0.15 0 0.51 0 0 0 </pose>

            <inertial>
                <mass>1</mass>
                <inertia>
                    <ixx>7.982e-03</ixx>
                    <iyy>7.982e-03</iyy>
					<izz>9.378e-04</izz>
                    <ixy>0</ixy>
                    <ixz>0</ixz>
                    <iyz>0</iyz>
                </inertia>
            </inertial>
            
            <collision name="left_base_collision">
                <geometry>
                    <mesh>
						<uri>model://simplified_biped/meshes/lower_leg_350mm.stl</uri>
					</mesh>
                </geometry>
            </collision>

            <visual name="left_base_visual">
                <geometry>
                    <mesh>
		   		 		<uri>model://simplified_biped/meshes/lower_leg_350mm.stl</uri>
					</mesh>
                </geometry>
            </visual>
    </link>

    <link name="left_knee">

        <self_collide>1</self_collide>
        <pose> 0.15 0 0.715 0 1.570796 0</pose>

        <inertial>
            <mass>2</mass>
            <inertia>
                <ixx>0.002</ixx>
                <iyy>18.5e-04</iyy>
                <izz>18.5e-04</izz>
                <ixy>0</ixy>
                <ixz>0</ixz>
                <iyz>0</iyz>
            </inertia>
        </inertial>

        <collision name="left_knee_collision">
            <geometry>
                <cylinder>
                    <radius>0.05</radius>
                    <length>0.06</length>
                </cylinder>
            </geometry>
        </collision>

        <visual name="left_knee_visual">
            <pose> 0 0 0 0 0 0</pose>
            <geometry>
                <cylinder>
                    <radius>0.05</radius>
                    <length>0.06</length>
                </cylinder>
            </geometry>
        </visual>
    </link>

    <link name="left_upper_leg">

        <self_collide>1</self_collide>

        <pose> 0.15 0 0.92 0 0 0 </pose> 

        <inertial>
            <mass>1</mass>
            <inertia>
                <ixx>7.982e-03</ixx>
                <iyy>7.982e-03</iyy>
                <izz>9.378e-04</izz>
                <ixy>0</ixy>
                <ixz>0</ixz>
                <iyz>0</iyz>
            </inertia>
        </inertial>

        <!-- To make them perfectly stacked: 0.65m height-->
        
        <collision name="left_upper_leg_collision">
            <geometry>
                <mesh>
					<uri>model://simplified_biped/meshes/upper_leg_350mm.stl</uri>
				</mesh>
            </geometry>
        </collision>

        <visual name="left_upper_leg_visual">
            <geometry>
                <mesh>
					<uri>model://simplified_biped/meshes/upper_leg_350mm.stl</uri>
				</mesh>
            </geometry>
        </visual>
    </link>

    <link name="left_foot_base">

        <self_collide>1</self_collide>
        <pose> 0.15 0 0.31 0 0 0</pose>

        <inertial>
            <mass>0.1</mass>
            <inertia>
                <ixx>2.733e-04</ixx>
                <iyy>5.666e-05</iyy>
                <izz>3.233e-04</izz>
                <ixy>0</ixy>
                <ixz>0</ixz>
                <iyz>0</iyz>
            </inertia>
        </inertial>

        <collision name="left_foot_base_collision">
            <geometry>
                <box>
                    <size> 0.08 0.18 0.02</size>
                </box>
            </geometry>
        </collision>

        <visual name="left_foot_base_visual">
            <geometry>
                <box>
                    <size> 0.08 0.18 0.02</size>
                </box>
            </geometry>
        </visual>
    </link>

    <link name="left_ankle">

        <self_collide>1</self_collide>
        <pose> 0.15 0 0.34 0 1.570796 0 </pose>

        <inertial>
            <mass>0.01</mass>
            <inertia>
                <ixx>0.000024</ixx>
                <iyy>0.000024</iyy>
                <izz>0.000004</izz>
                <ixy>0</ixy>
                <ixz>0</ixz>
                <iyz>0</iyz>
            </inertia>
        </inertial>

        <collision name="left_ankle_collision">
            <geometry>
                <cylinder>
                    <radius>0.008</radius>
                    <length>0.06</length>
                </cylinder>
            </geometry>
        </collision>

        <visual name="left_ankle_visual">
            <geometry>
                <cylinder>
                    <radius>0.008</radius>
                    <length>0.06</length>
                </cylinder>
            </geometry>
        </visual>
    </link>

    <link name="left_hip_axis_1">

        <self_collide>1</self_collide>
        <pose> 0.15 0 1.125 0 1.570796 0 </pose>

        <inertial>
            <mass>1</mass>
            <inertia>
                <ixx>1.249e-03</ixx>
                <iyy>9.250e-04</iyy>
                <izz>9.250e-04</izz>
                <ixy>0</ixy>
                <ixz>0</ixz>
                <iyz>0</iyz>
            </inertia>
        </inertial>

        <collision name="left_hip_axis_1_collision">
            <geometry>
                <cylinder>
                    <radius>0.05</radius>
                    <length>0.06</length>
                </cylinder>
            </geometry>
        </collision>

        <visual name="left_hip_axis_1_visual">
            <pose> 0 0 0 0 0 0</pose>
            <geometry>
                <cylinder>
                    <radius>0.05</radius>
                    <length>0.06</length>
                </cylinder>
            </geometry>
        </visual>
    </link>

    <link name="left_hip_axis_2">

        <self_collide>1</self_collide>
        <pose> 0.15 0 1.27 0 1.570796 1.570796 </pose>
        
        <inertial>
            <mass>1</mass>
            <inertia>
                <ixx>1.249e-03</ixx>
                <iyy>9.250e-04</iyy>
                <izz>9.250e-04</izz>
                <ixy>0</ixy>
                <ixz>0</ixz>
                <iyz>0</iyz>
            </inertia>
        </inertial>

        <collision name="left_hip_axis_2_collision">
            <geometry>
                <cylinder>
                    <radius>0.05</radius>
                    <length>0.06</length>
                </cylinder>
            </geometry>
        </collision>

        <visual name="left_hip_axis_2_visual">
            <pose> 0 0 0 0 0 0</pose>
            <geometry>
                <cylinder>
                    <radius>0.05</radius>
                    <length>0.06</length>
                </cylinder>
            </geometry>
        </visual>
    </link>

    <link name="left_hip_axis_3">

        <self_collide>1</self_collide>
        <pose> 0.15 0 1.415 0 0 0 </pose> <!--145mm from center of hip axis 2-->

        <inertial>
            <mass>1</mass>
            <inertia>
                <ixx>1.249e-03</ixx>
                <iyy>9.250e-04</iyy>
                <izz>9.250e-04</izz>
                <ixy>0</ixy>
                <ixz>0</ixz>
                <iyz>0</iyz>
            </inertia>
        </inertial>

        <collision name="left_hip_axis_3_collision">
            <geometry>
                <mesh>
					<uri>model://simplified_biped/meshes/actuator_scaled.stl</uri>
				</mesh>
            </geometry>
        </collision>

        <visual name="left_hip_axis_3_visual">
            <geometry>
                <mesh>
					<uri>model://simplified_biped/meshes/actuator_scaled.stl</uri>
				</mesh>
            </geometry>
        </visual>
    </link>

    <joint type="revolute" name="left_knee_lower_leg_joint">

        <pose> 0 0 0.205 0 0 0 </pose>

        <parent>left_knee</parent>

        <child>left_lower_leg</child>
        
        <axis>
            <xyz>1 0 0 </xyz>
            <initial_position>1</initial_position>
            <limit>
                <lower>-2.5</lower>
                <upper>2.5</upper>
            </limit>
        </axis>
    </joint>

    <joint type="revolute" name="left_hip_axis_1_upper_leg_joint">

        <pose> 0 0 0.205 0 0 0 </pose>

        <parent>left_hip_axis_1</parent>

        <child>left_upper_leg</child>

        <axis>
            <xyz>1 0 0 </xyz>
            <initial_position>1</initial_position>
            <limit>
                <lower>-2.5</lower>
                <upper>2.5</upper>
            </limit>
        </axis>
    </joint>

    <joint type="revolute" name="left_hip_axis_2_hip_axis_1_joint">
        <pose> -0.145 0 0 0 -1.570796 0 </pose>

        <parent>left_hip_axis_2</parent>
        <child>left_hip_axis_1</child>

        <axis>
            <xyz> 0 1 0 </xyz>
            <initial_position>1</initial_position>
            <limit>
                <lower>-2.5</lower>
                <upper>2.5</upper>
            </limit>
        </axis>
    </joint>

    <joint type="revolute" name="left_hip_axis_3_hip_axis_2_joint">
        <pose> -0.145 0 0 0 -1.5707 0 </pose>

        <parent>left_hip_axis_3</parent>
        <child>left_hip_axis_2</child>

        <axis>
            <xyz> 0 0 1 </xyz>
            <initial_position>1</initial_position>
            <limit>
                <lower>-1</lower>
                <upper>1</upper>
            </limit>
        </axis>
    </joint>

    <!--Change joint type back to revolute if actively driven ankle joint is needed-->
    <joint type="revolute" name="left_ankle_foot_base_joint">
        <pose> 0 0 0.03 0 0 0 </pose>

        <parent>left_ankle</parent>
        <child>left_foot_base</child>
        <axis>
            <xyz>1 0 0 </xyz>
            <initial_position>1</initial_position>
            <limit>
                <lower>-1.57</lower>
                <upper>1.57</upper>
            </limit>
        </axis>
    </joint>

    <joint type="fixed" name="left_knee_upper_leg_joint">
        <pose>0 0 0 0 0 0 </pose>
        <parent>left_upper_leg</parent>
        <child>left_knee</child>
    </joint>

    <joint type="fixed" name="left_ankle_lower_leg_joint">
        <pose> 0 0 0 0 0 0 </pose>
        <parent>left_lower_leg</parent>
        <child>left_ankle</child>
    </joint>

    <!--Right leg-->

    <link name="right_lower_leg">

        <self_collide>1</self_collide>

        <pose> -0.15 0 0.51 0 0 0 </pose>

            <inertial>
                <mass>0.1</mass>
                <inertia>
                    <ixx>7.982e-04</ixx>
                    <iyy>7.982e-04</iyy>
					<izz>9.391e-05</izz>
                    <ixy>0</ixy>
                    <ixz>0</ixz>
                    <iyz>0</iyz>
                </inertia>
            </inertial>
            
            <collision name="right_base_collision">
                <geometry>
                    <mesh>
		   		 		<uri>model://simplified_biped/meshes/lower_leg.stl</uri>
					</mesh>
                </geometry>
            </collision>

            <visual name="right_base_visual">
                <geometry>
                    <mesh>
		   		 		<uri>model://simplified_biped/meshes/lower_leg.stl</uri>
					</mesh>
                </geometry>
            </visual>
    </link>

    <link name="right_knee">

        <self_collide>1</self_collide>
        <pose> -0.15 0 0.715 0 1.570796 0</pose>

        <inertial>
            <mass>0.001</mass>
            <inertia>
                <ixx>0.000005</ixx>
                <iyy>0.000005</iyy>
                <izz>0.000007</izz>
                <ixy>0</ixy>
                <ixz>0</ixz>
                <iyz>0</iyz>
            </inertia>
        </inertial>

        <collision name="right_knee_collision">
            <geometry>
                <cylinder>
                    <radius>0.05</radius>
                    <length>0.06</length>
                </cylinder>
            </geometry>
        </collision>

        <visual name="right_knee_visual">
            <pose> 0 0 0 0 0 0</pose>
            <geometry>
                <cylinder>
                    <radius>0.05</radius>
                    <length>0.06</length>
                </cylinder>
            </geometry>
        </visual>
    </link>

    <link name="right_upper_leg">

        <self_collide>1</self_collide>

        <pose> -0.15 0 0.92 0 0 0 </pose> 

        <inertial>
            <mass>0.1</mass>
            <inertia>
                <ixx>7.982e-04</ixx>
                <iyy>7.982e-04</iyy>
                <izz>9.391e-05</izz>
                <ixy>0</ixy>
                <ixz>0</ixz>
                <iyz>0</iyz>
            </inertia>
        </inertial>

        <!-- To make them perfectly stacked: 0.65m height-->
        
        <collision name="right_upper_leg_collision">
            <geometry>
				<mesh>
					<uri>model://simplified_biped/meshes/upper_leg.stl</uri>
				</mesh>
            </geometry>
        </collision>

        <visual name="right_upper_leg_visual">
            <geometry>
            	<mesh>
		   		 	<uri>model://simplified_biped/meshes/upper_leg.stl</uri>
				</mesh>
            </geometry>
        </visual>
    </link>

    <link name="right_foot_base">

        <self_collide>1</self_collide>
        <pose> -0.15 0 0.31 0 0 0</pose>

        <inertial>
            <mass>0.01</mass>
            <inertia>
                <ixx>2.733e-05</ixx>
                <iyy>5.666e-06</iyy>
                <izz>3.233e-05</izz>
                <ixy>0</ixy>
                <ixz>0</ixz>
                <iyz>0</iyz>
            </inertia>
        </inertial>

        <collision name="right_foot_base_collision">
            <geometry>
                <box>
                    <size> 0.08 0.18 0.02</size>
                </box>
            </geometry>
        </collision>

        <visual name="right_foot_base_visual">
            <geometry>
                <box>
                    <size> 0.08 0.18 0.02</size>
                </box>
            </geometry>
        </visual>
    </link>

    <link name="right_ankle">

        <self_collide>1</self_collide>
        <pose> -0.15 0 0.34 0 1.570796 0 </pose>

        <inertial>
            <mass>0.001</mass>
            <inertia>
                <ixx>0.0000024</ixx>
                <iyy>0.0000024</iyy>
                <izz>0.0000004</izz>
                <ixy>0</ixy>
                <ixz>0</ixz>
                <iyz>0</iyz>
            </inertia>
        </inertial>

        <collision name="right_ankle_collision">
            <geometry>
                <cylinder>
                    <radius>0.008</radius>
                    <length>0.06</length>
                </cylinder>
            </geometry>
        </collision>

        <visual name="right_ankle_visual">
            <geometry>
                <cylinder>
                    <radius>0.008</radius>
                    <length>0.06</length>
                </cylinder>
            </geometry>
        </visual>
    </link>

    <link name="right_hip_axis_1">

        <self_collide>1</self_collide>
        <pose> -0.15 0 1.125 0 1.570796 0 </pose>

        <inertial>
            <mass>0.1</mass>
            <inertia>
                <ixx>1.249e-04</ixx>
                <iyy>9.241e-05</iyy>
                <izz>9.241e-05</izz>
                <ixy>0</ixy>
                <ixz>0</ixz>
                <iyz>0</iyz>
            </inertia>
        </inertial>

        <collision name="right_hip_axis_1_collision">
            <geometry>
                <cylinder>
                    <radius>0.05</radius>
                    <length>0.06</length>
                </cylinder>
            </geometry>
        </collision>

        <visual name="right_hip_axis_1_visual">
            <pose> 0 0 0 0 0 0</pose>
            <geometry>
                <cylinder>
                    <radius>0.05</radius>
                    <length>0.06</length>
                </cylinder>
            </geometry>
        </visual>
    </link>

    <link name="right_hip_axis_2">

        <self_collide>1</self_collide>
        <pose> -0.15 0 1.27 0 1.570796 1.570796 </pose>
        
        <inertial>
            <mass>0.1</mass>
            <inertia>
                <ixx>1.249e-04</ixx>
                <iyy>9.241e-05</iyy>
                <izz>9.241e-05</izz>
                <ixy>0</ixy>
                <ixz>0</ixz>
                <iyz>0</iyz>
            </inertia>
        </inertial>

        <collision name="right_hip_axis_2_collision">
            <geometry>
                <cylinder>
                    <radius>0.05</radius>
                    <length>0.06</length>
                </cylinder>
            </geometry>
        </collision>

        <visual name="right_hip_axis_2_visual">
            <pose> 0 0 0 0 0 0</pose>
            <geometry>
                <cylinder>
                    <radius>0.05</radius>
                    <length>0.06</length>
                </cylinder>
            </geometry>
        </visual>
    </link>

    <link name="right_hip_axis_3">

        <self_collide>1</self_collide>
        <pose> -0.15 0 1.415 0 0 0 </pose> <!--145mm from center of hip axis 2-->

        <inertial>
            <mass>0.1</mass>
            <inertia>
                <ixx>1.249e-04</ixx>
                <iyy>9.241e-05</iyy>
                <izz>9.241e-05</izz>
                <ixy>0</ixy>
                <ixz>0</ixz>
                <iyz>0</iyz>
            </inertia>
        </inertial>

        <collision name="right_hip_axis_3_collision">
            <geometry>
                <mesh>
					<uri>model://simplified_biped/meshes/actuator_scaled.stl</uri>
				</mesh>
            </geometry>
        </collision>

        <visual name="right_hip_axis_3_visual">
            <geometry>
                <mesh>
					<uri>model://simplified_biped/meshes/actuator_scaled.stl</uri>
				</mesh>
            </geometry>
        </visual>
    </link>

    <joint type="revolute" name="right_knee_lower_leg_joint">

        <pose> 0 0 0.205 0 0 0 </pose>

        <parent>right_knee</parent>

        <child>right_lower_leg</child>
        
        <axis>
            <xyz>1 0 0 </xyz>
            <limit>
                <lower>-2</lower>
                <upper>2</upper>
            </limit>
        </axis>
    </joint>

    <joint type="revolute" name="right_hip_axis_1_upper_leg_joint">

        <pose> 0 0 0.205 0 0 0 </pose>

        <parent>right_hip_axis_1</parent>

        <child>right_upper_leg</child>

        <axis>
            <xyz>1 0 0 </xyz>
            <limit>
                <lower>-2</lower>
                <upper>2</upper>
            </limit>
        </axis>
    </joint>

    <joint type="revolute" name="right_hip_axis_2_hip_axis_1_joint">
        <pose> -0.145 0 0 0 -1.570796 0 </pose>

        <parent>right_hip_axis_2</parent>
        <child>right_hip_axis_1</child>

        <axis>
            <xyz> 0 1 0 </xyz>
            <limit>
                <lower>-2</lower>
                <upper>2</upper>
            </limit>
        </axis>
    </joint>

    <joint type="revolute" name="right_hip_axis_3_hip_axis_2_joint">
        <pose> -0.145 0 0 0 -1.5707 0 </pose>

        <parent>right_hip_axis_3</parent>
        <child>right_hip_axis_2</child>

        <axis>
            <xyz> 0 0 1 </xyz>
            <limit>
                <lower>-2</lower>
                <upper>2</upper>
            </limit>
        </axis>
    </joint>

    <!--Change joint type back to revolute if actively driven ankle joint is needed-->
    <joint type="revolute" name="right_ankle_foot_base_joint">
        <pose> 0 0 0.03 0 0 0 </pose>

        <parent>right_ankle</parent>
        <child>right_foot_base</child>
        <limit>
            <lower>0</lower>
            <upper>0</upper>
        </limit>
        <axis>
            <xyz>1 0 0 </xyz>
            <limit>
                <lower>-2</lower>
                <upper>2</upper>
            </limit>
        </axis>
    </joint>


    <joint type="fixed" name="right_knee_upper_leg_joint">
        <pose>0 0 0 0 0 0 </pose>
        <parent>right_upper_leg</parent>
        <child>right_knee</child>
    </joint>

    <joint type="fixed" name="right_ankle_lower_leg_joint">
        <pose> 0 0 0 0 0 0 </pose>
        <parent>right_lower_leg</parent>
        <child>right_ankle</child>
    </joint>

    <joint type="fixed" name="left_torso_connection_joint">
        <pose> 0 0 0 0 0 0 </pose>
        <parent>torso_connection</parent>
        <child>left_hip_axis_3</child>
    </joint>

    <joint type="fixed" name="right_torso_connection_joint">
        <pose> 0 0 0 0 0 0 </pose>
        <parent>torso_connection</parent>
        <child>right_hip_axis_3</child>
    </joint>


</model>
</sdf>
